Workbook
Name _Toc11120784: 'Documents Management'!$A$3
Name _Toc57468547: 'Documents Management'!$A$12
Name _Toc57468548: 'Documents Management'!$A$20

Sheet Documents Management
A1: DOCUMENT REGISTER — Reverse Pump Energy Recovery PLM
A2: Program | B2: Underground pressure-reducing stations / reverse pump-as-turbine generation | C2: Lifecycle | D2: Project Proposal → Design → Validation & Testing → Commissioning → O&M | E2: As of | F2: 42268 | G2: Owner | H2: PLM / Configuration Mgmt
A3: Governance | B3: Owned full lifecycle delivery under stage-gate control | C3: Reporting | D3: KPI-driven technical + financial + operational cadence | E3: Cadence | F3: Monthly ops / quarterly steering
A5: TC Document ID | B5: Revision | C5: Stage | D5: Document Type | E5: Controlled Deliverable | F5: Owner | G5: Release State | H5: Release Date
A6: TC-DOC-0001 | B6: A | C6: Project Proposal | D6: Business Case | E6: Initial 2012 proposal for energy recovery at underground pressure stations | F6: PMO | G6: Released | H6: 40983
A7: TC-DOC-0002 | B7: B | C7: Project Proposal | D7: Feasibility | E7: 14-station candidate screening, hydraulic map and spatial constraints | F7: Hydraulics | G7: Released | H7: 41151
A8: TC-DOC-0003 | B8: C | C8: Project Proposal | D8: Financial Model | E8: Target EPC CapEx $14.0M, payback 5.0 years, IRR 10–13% | F8: Finance | G8: Released | H8: 41263
A9: TC-DOC-0101 | B9: A | C9: Design | D9: System Requirements | E9: PAT/turbine, generator, bypass valve, MCC, relay protection and SCADA requirements | F9: Systems Eng. | G9: Released | H9: 41382
A10: TC-DOC-0102 | B10: B | C10: Design | D10: EBOM Baseline | E10: Engineering BOM for hydraulic skid, electrical package and instrumentation | F10: PLM Admin | G10: Released | H10: 41600
A11: TC-DOC-0103 | B11: B | C11: Design | D11: Interface Control | E11: Mechanical, electrical, civil and SCADA interface control document | F11: Systems Eng. | G11: Released | H11: 41684
A12: TC-DOC-0104 | B12: C | C12: Design | D12: HAZOP / LOPA | E12: HAZOP actions for bypass isolation, overspeed, flooding and LOTO | F12: HSE | G12: Released | H12: 41887
A13: TC-DOC-0201 | B13: A | C13: Validation & Testing | D13: DVP&R | E13: Hydraulic duty, vibration, protection trip and bypass validation plan | F13: Validation | G13: Released | H13: 42027
A14: TC-DOC-0202 | B14: A | C14: Validation & Testing | D14: Factory Test | E14: Generator, MCC, protection relay and FAT acceptance record | F14: Electrical | G14: Released | H14: 42153
A15: TC-DOC-0203 | B15: B | C15: Validation & Testing | D15: Pilot Report | E15: 0.25 MW pilot, $0.75M CapEx, 18-month development close-out | F15: PMO | G15: Released | H15: 42277
A16: TC-DOC-0301 | B16: A | C16: Commissioning | D16: Method Statement | E16: Wet commissioning, grid synchronization and trip-test protocol | F16: Commissioning | G16: Released | H16: 42419
A17: TC-DOC-0302 | B17: A | C17: Commissioning | D17: As-Built Pack | E17: As-built drawings, cable schedules, valve datasheets and PLC backups | F17: Site Eng. | G17: Released | H17: 42579
... A24: TC-DOC-0407 | B24: A | C24: O&M | D24: PLM Data Dictionary | E24: Teamcenter item/revision/ECN/status definitions for refresh control | F24: PLM Admin | G24: Released | H24: 46183

Sheet BOM Management (EBOM_MBOM)
A1: EBOM → MBOM BASELINE — Pump-as-Turbine / Generator Skid
A3: Item ID | B3: Rev | C3: System | D3: EBOM Qty | E3: MBOM Qty | F3: Make/Buy | G3: Supplier / Work Center | H3: Unit Cost $k | I3: Lifecycle State | J3: Change Ref
A4: PAT-ASSY-250KW | B4: C | C4: Hydraulic Turbine Package | D4: 1 | E4: 1 | F4: Buy | G4: PAT OEM / Hydraulics | H4: 310 | I4: Released | J4: ECN-014
A5: GEN-ASSY-480V | B5: B | C5: Generator | D5: 1 | E5: 1 | F5: Buy | G5: Generator OEM | H5: 185 | I5: Released | J5: ECN-008
A6: SKID-FRAME-SS | B6: B | C6: Mechanical Skid | D6: 1 | E6: 1 | F6: Make | G6: Fabrication Shop | H6: 95 | I6: Released | J6: ECN-006
A7: BYP-VLV-MOD | B7: C | C7: Bypass / Isolation Valves | D7: 3 | E7: 3 | F7: Buy | G7: Valve OEM | H7: 72 | I7: Released | J7: ECN-009
A8: PIPE-SPOOL-SS316 | B8: C | C8: Pipe Spools | D8: 6 | E8: 7 | F8: Make | G8: Fabrication Shop | H8: 54 | I8: Released | J8: ECN-006
A9: MCC-PNL-480V | B9: B | C9: Electrical MCC | D9: 1 | E9: 1 | F9: Buy | G9: Panel Builder | H9: 140 | I9: Released | J9: ECN-008
A10: REL-PROT-GRID | B10: B | C10: Protection Relay | D10: 1 | E10: 1 | F10: Buy | G10: Protection OEM | H10: 38 | I10: Released | J10: ECN-008
A11: SCADA-PLC-IO | B11: C | C11: Controls / SCADA | D11: 1 | E11: 1 | F11: Buy | G11: Controls Integrator | H11: 112 | I11: Released | J11: ECN-011
A12: METER-REV-ANSI | B12: B | C12: Revenue Metering | D12: 1 | E12: 1 | F12: Buy | G12: Meter OEM | H12: 24 | I12: Released | J12: ECN-011
A13: VFD-BRAKE-OPT | B13: A | C13: Power Electronics | D13: 1 | E13: 1 | F13: Buy | G13: Drive OEM | H13: 78 | I13: Released | J13: ECN-010
A14: INS-VIB-TEMP | B14: B | C14: Instrumentation | D14: 1 | E14: 1 | F14: Buy | G14: Instrumentation Supplier | H14: 31 | I14: Released | J14: ECN-012
A15: CIVIL-ANCHOR-KIT | B15: A | C15: Civil / Anchors | D15: 1 | E15: 1 | F15: Make | G15: Civil Contractor | H15: 44 | I15: Released | J15: ECN-005
... A28: PLM-CONFIG-PKG | B28: A | C28: PLM Configuration | D28: 1 | E28: 1 | F28: Service | G28: PLM Admin | H28: 16 | I28: Released | J28: ECN-001
C30: Summary | D30: Formula | E30: Unit | F30: Status
C31: Total reference MBOM unit cost | D31: =SUM(H4:H28) -> 1596 | E31: $k / station package | F31: OK
C32: Qty mismatch count | D32: =SUMPRODUCT(--(D4:D28<>E4:E28)) -> 1 | E32: count | F32: Review pipe spool planned extra

Sheet Change Management (Change_Log)
A1: Change Log
A3: Change ID | B3: Date | C3: Stage | D3: ECR / ECO Type | E3: Description | F3: Affected System | G3: Priority | H3: Time Impact | I3: CapEx Impact $k | J3: OPEX Impact $k/yr | K3: Disposition | L3: Owner | N3: KPI | O3: Value | P3: Status
A4: CHG-001 | B4: 40959 | C4: Project Proposal | D4: Scope Baseline | E4: Create PLM baseline for reverse pump energy recovery opportunity | F4: Program | G4: High | H4: +10 days | I4: 45 | J4: 0 | K4: Accepted | L4: PMO | N4: Total changes | O4: =COUNTA(A4:A27) -> 24 | P4: OK
A5: CHG-002 | B5: 41043 | C5: Project Proposal | D5: Feasibility | E5: Add 14-station hydraulic survey and pressure head capture | F5: Hydraulics | G5: Critical | H5: +30 days | I5: 120 | J5: 0 | K5: Accepted | L5: Hydraulics | N5: Accepted / closed | O5: =COUNTIF(K4:K27,"Accepted")+COUNTIF(K4:K27,"Closed with lessons")+COUNTIF(K4:K27,"Rejected from scope") -> 24 | P5: OK
A6: CHG-003 | B6: 41159 | C6: Project Proposal | D6: Financial | E6: Add EPC target CapEx $14M and hurdle payback/IRR controls | F6: Finance | G6: High | H6: +5 days | I6: 0 | J6: 0 | K6: Accepted | L6: Finance | N6: Critical changes | O6: =COUNTIF(G4:G27,"Critical") -> 8 | P6: Watch
A7: CHG-004 | B7: 41390 | C7: Design | D7: Requirements | E7: Split sites by Group A/B and define station-level KPI schema | F7: Systems | G7: Medium | H7: +5 days | I7: 10 | J7: 0 | K7: Accepted | L7: Controls | N7: CapEx impact $k | O7: =SUM(I4:I27) -> 945 | P7: Tie to CBA
A8: CHG-005 | B8: 41600 | C8: Design | D8: EBOM | E8: Expand EBOM for PAT, generator, bypass valves, pipe spools and controls | F8: Mechanical / Electrical | G8: High | H8: +20 days | I8: 85 | J8: 0 | K8: Accepted | L8: PLM Admin | N8: Annual OPEX impact $k | O8: =SUM(J4:J27) -> 78 | P8: Tie to CBA
A9: CHG-006 | B9: 41530 | C9: Design | D9: Civil | E9: Eliminate ST-07 due severe access and physical space constraints | F9: Civil / Site | G9: Critical | H9: -1 station | I9: 0 | J9: 0 | K9: Rejected from scope | L9: Civil | N9: External link remediation | O9: 0 | P9: PASS
A10: CHG-007 | B10: 41673 | C10: Design | D10: Materials | E10: Revise pipe spool material to SS316 after corrosion review | F10: Mechanical | G10: High | H10: +12 days | I10: 55 | J10: 8 | K10: Accepted | L10: Mechanical
A11: CHG-008 | B11: 41814 | C11: Design | D11: Electrical | E11: Add MCC/protection relay package and grid interconnection study | F11: Electrical | G11: Critical | H11: +25 days | I11: 160 | J11: 5 | K11: Accepted | L11: Electrical
A12: CHG-009 | B12: 41925 | C12: Design | D12: Feasibility | E12: Eliminate ST-12 due installation risk and confined-space conflict | F12: Site Engineering | G12: Critical | H12: -1 station | I12: 0 | J12: 0 | K12: Rejected from scope | L12: Site Eng.
A13: CHG-010 | B13: 42027 | C13: Validation & Testing | D13: DVP&R | E13: Add overspeed trip, vibration acceptance and hydraulic duty-point testing | F13: Validation | G13: High | H13: +18 days | I13: 40 | J13: 3 | K13: Accepted | L13: Validation
A14: CHG-011 | B14: 42153 | C14: Validation & Testing | D14: Controls | E14: Add SCADA, revenue metering and historian integration requirements | F14: Controls | G14: High | H14: +18 days | I14: 95 | J14: 12 | K14: Accepted | L14: Controls
A15: CHG-012 | B15: 42277 | C15: Validation & Testing | D15: Pilot Closeout | E15: Close 0.25 MW pilot after 18-month development and update lessons learned | F15: Pilot | G15: High | H15: 0 days | I15: 0 | J15: 0 | K15: Accepted | L15: PMO
A16: CHG-013 | B16: 42419 | C16: Commissioning | D16: HSE | E16: Add HAZOP/LOTO actions before commissioning release | F16: HSE | G16: Critical | H16: +20 days | I16: 40 | J16: 4 | K16: Accepted | L16: HSE
A17: CHG-014 | B17: 42579 | C17: Commissioning | D17: Procurement | E17: Finalize PAT package quotes and release construction MBOM | F17: Procurement | G17: Critical | H17: +15 days | I17: 210 | J17: 0 | K17: Accepted | L17: Procurement
A18: CHG-015 | B18: 42766 | C18: O&M | D18: Spares | E18: Add O&M spare kit and operator training deliverables | F18: O&M | G18: Medium | H18: +8 days | I18: 35 | J18: 18 | K18: Accepted | L18: O&M
A19: CHG-016 | B19: 43280 | C19: O&M | D19: KPI Reporting | E19: Establish uptime, generation, downtime-cause and financial KPI dashboard | F19: Operations | G19: High | H19: +5 days | I19: 18 | J19: 7 | K19: Accepted | L19: Operations
A20: CHG-017 | B20: 43546 | C20: O&M | D20: Field Attrition | E20: Decommission ST-09 after repeated bearing/vibration failures; return failure data to PLM | F20: Reliability | G20: Critical | H20: -1 station | I20: 0 | J20: -18 | K20: Closed with lessons | L20: Reliability
A21: CHG-018 | B21: 44183 | C21: O&M | D21: Governance | E21: Formalize monthly operating review and quarterly steering escalation path | F21: PMO | G21: High | H21: 0 days | I21: 0 | J21: 0 | K21: Accepted | L21: PMO
... A27: CHG-024 | B27: 46183 | C27: O&M | D27: Report Refresh | E27: Refresh executive report and remove unresolved external workbook link prompt | F27: PLM / Finance | G27: Critical | H27: 0 days | I27: 0 | J27: 0 | K27: Accepted | L27: PLM Admin

Sheet Change Management (ECN)
A1: ECN | B1: 41043 | C1: CHG-002 | D1: SITE-SURVEY-PKG / B | E1: Project Proposal | F1: Need station-level hydraulic head and flow data | G1: Survey template released | H1: Development budget added | I1: G1 | J1: Hydraulics | K1: PMO | L1: 120 | M1: 0 | N1: High | O1: Medium | P1: Released | Q1: B
A2: ECN-001 | B2: 41530 | C2: CHG-006 | D2: ST-07 Site Record | E2: Design | F2: Physical envelope incompatible with skid and safe access | G2: Station removed before execution | H2: Avoided stranded CapEx | I2: G1 | J2: Civil | K2: Steering | L2: 0 | M2: 0 | N2: Very High | O2: Closed | P2: Released | Q2: N/A
A3: ECN-003 | B3: 41673 | C3: CHG-007 | D3: PIPE-SPOOL-SS316 / C | E3: Design | F3: Corrosion risk under condensate and washdown exposure | G3: SS316 spool material released | H3: CapEx +$55k; OPEX +$8k/yr | I3: G2 | J3: Mechanical | K3: HSE | L3: 55 | M3: 8 | N3: High | O3: Low | P3: Released | Q3: C
A4: ECN-005 | B4: 41814 | C4: CHG-008 | D4: MCC-PNL-480V / B | E4: Design | F4: Protection and synchronization requirements incomplete | G4: MCC/protection panel released | H4: Included in EPC target | I4: G2 | J4: Electrical | K4: Quality | L4: 160 | M4: 5 | N4: High | O4: Medium | P4: Released | Q4: B
A5: ECN-006 | B5: 41925 | C5: CHG-009 | D5: ST-12 Site Record | E5: Design | F5: Confined-space and installation risk exceeds threshold | G5: Station removed before execution | H5: Avoided high-risk spend | I5: G1 | J5: Site Eng. | K5: Steering | L5: 0 | M5: 0 | N5: Very High | O5: Closed | P5: Released | Q5: N/A
A6: ECN-008 | B6: 42027 | C6: CHG-010 | D6: VFD-BRAKE-OPT / A | E6: Validation & Testing | F6: Overspeed and transient trip testing identified braking requirement | G6: Braking option released | H6: CapEx +$40k | I6: G3 | J6: Validation | K6: Electrical | L6: 40 | M6: 3 | N6: High | O6: Medium | P6: Released | Q6: A
A7: ECN-007 | B7: 42153 | C7: CHG-011 | D7: SCADA-PLC-IO / C | E7: Validation & Testing | F7: Remote monitoring and revenue reporting require historian data | G7: SCADA/historian scope released | H7: OPEX data capture improves reporting | I7: G3 | J7: Controls | K7: Operations | L7: 95 | M7: 12 | N7: Medium | O7: Low | P7: Released | Q7: C
A8: ECN-010 | B8: 42419 | C8: CHG-013 | D8: FAT-SAT-PKG / A | E8: Commissioning | F8: Safety and test evidence needed before wet commissioning | G8: FAT/SAT dossier mandatory | H8: CapEx +$40k | I8: G4 | J8: HSE | K8: Quality | L8: 40 | M8: 4 | N8: High | O8: Low | P8: Released | Q8: A
A9: ECN-011 | B9: 42579 | C9: CHG-014 | D9: PAT-ASSY-250KW / C | E9: Commissioning | F9: Supplier final quote package and PAT curves received | G9: PAT package released | H9: CapEx +$210k | I9: G4 | J9: Procurement | K9: Engineering | L9: 210 | M9: 0 | N9: Medium | O9: Low | P9: Released | Q9: C
A10: ECN-013 | B10: 42766 | C10: CHG-015 | D10: SPARES-YR1-KIT / A | E10: O&M | F10: Initial operating period needs spare bearings, seals, sensors | G10: Spares kit and training released | H10: CapEx +$35k; OPEX +$18k/yr | I10: G5 | J10: O&M | K10: Finance | L10: 35 | M10: 18 | N10: Medium | O10: Low | P10: Released | Q10: A
A11: ECN-014 | B11: 42766 | C11: CHG-017 | D11: ST-09 Site Record | E11: O&M | F11: Repeated bearing/vibration failures after installation | G11: Station decommissioned; DVP&R updated | H11: Reduced future OPEX drag | I11: G5 | J11: Reliability | K11: Steering | L11: 0 | M11: -18 | N11: Very High | O11: Closed | P11: Released | Q11: N/A
A12: ECN-015 | B12: 42766 | C12: CHG-021 | D12: OVERHAUL-RESERVE / A | E12: O&M | F12: Lifecycle reserve needed for overhaul and major maintenance | G12: Annual reserve added to economics | H12: Net cash-flow adjusted for IRR | I12: G5 | J12: Finance | K12: O&M | L12: 0 | M12: 300 | N12: Medium | O12: Low | P12: Released | Q12: A
... A14: ECN-021 | B14: 42766 | C14: CHG-024 | D14: Executive Pack / D | E14: O&M | F14: Steering pack needed full technical and financial refresh | G14: Dashboard and executive report rebuilt | H14: Reporting improvement | I14: G5 | J14: PMO | K14: Steering | L14: 0 | M14: 0 | N14: Medium | O14: Low | P14: Released | Q14: D
A15: ECN-024
A16: ECN-025

Sheet Validation & Release Management
A1: VALIDATION & RELEASE MANAGEMENT
A3: Gate | B3: Stage | C3: Target Date | D3: Exit Criteria | E3: Technical Evidence | F3: Financial Evidence | G3: Operational Evidence | H3: Decision | I3: Escalation Path | J3: Owner
A4: G0 | B4: Project Proposal | C4: 40983 | D4: Opportunity defined and PLM baseline opened | E4: Pressure energy recovery concept note | F4: Initial EPC budget | G4: NPI charter | H4: Pass | I4: PMO → Steering | J4: PMO
A5: G1 | B5: Feasibility Filtering | C5: 41263 | D5: 14 candidates screened; unsafe sites removed | E5: Hydraulic survey and envelope checks | F5: Pilot $0.75M / 0.25MW / 18 months approved | G5: Site access risk review | H5: Pass with attrition | I5: Engineering → Steering | J5: Hydraulics
A6: G2 | B6: Design Freeze | C6: 41925 | D6: EBOM, interfaces, HAZOP and grid study released | E6: PAT curves, generator sizing, protection settings | F6: CapEx bridge within $14M target | G6: Procurement readiness | H6: Pass | I6: Design Authority | J6: Systems Eng.
A7: G3 | B7: Validation & Testing | C7: 42277 | D7: DVP&R and pilot close-out accepted | E7: FAT, SAT, overspeed, vibration, thermal tests | F7: Pilot learnings incorporated | G7: Operator training plan | H7: Pass | I7: Validation Board | J7: Validation
A8: G4 | B8: Commissioning | C8: 42579 | D8: Wet commissioning and grid sync evidence complete | E8: Trip tests, bypass operation, SCADA points | F8: Installed cost and forecast OPEX refreshed | G8: Site handover | H8: Pass | I8: Commissioning Board | J8: Commissioning
A9: G5 | B9: O&M Release | C9: 42400 | D9: 11 operating stations transitioned to KPI governance | E9: Reliability alarms, historian data, maintenance plan | F9: Payback / IRR tracked monthly/quarterly | G9: Monthly ops review | H9: Pass / monitor | I9: Operations → Steering | J9: O&M
A10: G5-FB | B10: Field Attrition Feedback | C10: 42816 | D10: ST-09 decommissioned and lessons pushed to PLM | E10: Bearing/vibration failure data attached to DVP&R | F10: OPEX risk reduced after removal | G10: Corrective actions closed | H10: Closed with lessons | I10: Reliability Board | J10: Reliability
A12: Validation Test ID | B12: System | C12: Acceptance Criteria | D12: Coverage | E12: Result | F12: Defect Count | G12: Corrective Action | H12: Release Impact | I12: Owner | J12: Status
A13: VAL-001 | B13: Hydraulic PAT | C13: Duty point within ±5% of curve | D13: Pilot + 11 active stations | E13: Pass | F13: 0 | G13: None | H13: Release | I13: Hydraulics | J13: Closed
A14: VAL-002 | B14: Generator | C14: Temperature rise within OEM class | D14: FAT all generator packages | E14: Pass | F14: 1 | G14: Cooling airflow note added | H14: Release | I14: Electrical | J14: Closed
A15: VAL-003 | B15: Protection Relay | C15: Trip selectivity and anti-islanding verified | D15: All commissioned stations | E15: Pass | F15: 0 | G15: None | H15: Release | I15: Electrical | J15: Closed
A16: VAL-004 | B16: Bypass Valve | C16: Fail-safe bypass open on trip/loss of power | D16: All commissioned stations | E16: Pass | F16: 2 | G16: Valve actuator setting revised | H16: Release after CA | I16: Mechanical | J16: Closed
A17: VAL-005 | B17: Vibration | C17: RMS vibration below alarm limit | D17: Pilot and operating stations | E17: Pass with monitor | F17: 1 | G17: Quarterly vibration trend | H17: Monitor | I17: Reliability | J17: Open monitor
A18: VAL-006 | B18: SCADA Historian | C18: Revenue and downtime tags captured | D18: 11 operating stations | E18: Pass | F18: 0 | G18: None | H18: Release | I18: Controls | J18: Closed
A19: VAL-007 | B19: HAZOP / LOTO | C19: All category A actions closed before wet commissioning | D19: All stations | E19: Pass | F19: 0 | G19: None | H19: Release | I19: HSE | J19: Closed
A20: VAL-008 | B20: Civil Access | C20: Safe maintenance envelope and lifting plan | D20: 14 candidates | E20: Fail for 2 | F20: 2 | G20: Remove ST-07/ST-12 | H20: Scope attrition | I20: Civil | J20: Closed
A21: VAL-009 | B21: Commercial Case | C21: Payback ≤5 years and IRR 10–13% | D21: Portfolio case | E21: Pass | F21: 0 | G21: Refresh quarterly | H21: Steering report | I21: Finance | J21: Closed
A22: VAL-010 | B22: Uptime KPI | C22: Operating uptime in 96–99% band | D22: Monthly O&M data | E22: Pass | F22: 0 | G22: Escalate if <96% | H22: O&M release | I22: Operations | J22: Live
A23: VAL-011 | B23: Cyber / OT | C23: Historian naming and OT access control implemented | D23: 11 stations | E23: Pass | F23: 0 | G23: Annual access review | H23: O&M release | I23: IT/OT | J23: Live
A24: VAL-012 | B24: Failure Feedback | C24: Field failure lessons fed into PLM and DVP&R | D24: ST-09 | E24: Pass | F24: 0 | G24: DVP&R updated | H24: Closed loop | I24: Reliability | J24: Closed
... A26: VAL-014 | B26: Stage-Gate Traceability | C26: Each gate has technical, financial and operating evidence | D26: All gates | E26: Pass | F26: 0 | G26: Quarterly audit | H26: Governance | I26: PMO | J26: Live

Sheet Risk Management
A1: RISK MANAGEMENT + NPI ATTRITION - 14 candidate stations to 11 operating assets
A3: Station | B3: Group | C3: Stage Outcome | D3: Commissioned | E3: Operating Status | F3: Capacity MW | G3: Uptime % | H3: Annual GWh | I3: CapEx M$ | J3: Key Constraint / Failure Mode | K3: Tech Gate | L3: Finance Gate | M3: Ops Gate | N3: Residual Risk | O3: PLM Feedback
A4: ST-01 | B4: A | C4: Operating | D4: 42510 | E4: Active | F4: 0.26 | G4: 0.982 | H4: =F4*8760*G4/1000 -> 2.2366032 | I4: 1.24 | J4: Normal PRV replacement envelope | K4: Pass | L4: Pass | M4: Pass | N4: Low | O4: Baseline retained
A5: ST-02 | B5: A | C5: Operating | D5: 42531 | E5: Active | F5: 0.24 | G5: 0.976 | H5: =F5*8760*G5/1000 -> 2.0519424 | I5: 1.18 | J5: High moisture controlled by enclosure | K5: Pass | L5: Pass | M5: Pass | N5: Low | O5: Maintenance note
A6: ST-03 | B6: A | C6: Operating | D6: 42559 | E6: Active | F6: 0.25 | G6: 0.989 | H6: =F6*8760*G6/1000 -> 2.16591 | I6: 1.25 | J6: Noise abatement required | K6: Pass | L6: Pass | M6: Pass | N6: Low | O6: Acoustic kit added
A7: ST-04 | B7: A | C7: Operating | D7: 42594 | E7: Active | F7: 0.28 | G7: 0.971 | H7: =F7*8760*G7/1000 -> 2.3816688 | I7: 1.3 | J7: Civil anchors upgraded | K7: Pass | L7: Pass | M7: Pass | N7: Medium | O7: Anchor kit standard
A8: ST-05 | B8: A | C8: Operating | D8: 42629 | E8: Active | F8: 0.23 | G8: 0.968 | H8: =F8*8760*G8/1000 -> 1.9503264 | I8: 1.16 | J8: Valve actuator tuning | K8: Pass | L8: Pass | M8: Pass | N8: Medium | O8: Valve setting CA
A9: ST-06 | B9: A | C9: Operating | D9: 42657 | E9: Active | F9: 0.25 | G9: 0.981 | H9: =F9*8760*G9/1000 -> 2.14839 | I9: 1.22 | J9: SCADA tag mapping | K9: Pass | L9: Pass | M9: Pass | N9: Low | O9: Historian standard
A10: ST-07 | B10: A | C10: Filtered out | D10: N/A | E10: Eliminated pre-execution | F10: 0 | G10: 0 | H10: 0 | I10: 0 | J10: Severe physical space and safe access constraint | K10: Fail | L10: N/A | M10: N/A | N10: Closed | O10: Pre-execution elimination
A11: ST-08 | B11: B | C11: Operating | D11: 42692 | E11: Active | F11: 0.27 | G11: 0.963 | H11: =F11*8760*G11/1000 -> 2.2776876 | I11: 1.29 | J11: Bypass valve access conflict resolved | K11: Pass | L11: Pass | M11: Pass | N11: Medium | O11: Access kit added
A12: ST-09 | B12: B | C12: Field attrition | D12: 42755 | E12: Decommissioned | F12: 0.25 | G12: 0 | H12: 0 | I12: 1.08 | J12: Bearing/vibration failures under transient duty | K12: Pass | L12: Pass | M12: Fail | N12: Closed | O12: Failure data to DVP&R
A13: ST-10 | B13: B | C13: Operating | D13: 42783 | E13: Active | F13: 0.24 | G13: 0.974 | H13: =F13*8760*G13/1000 -> 2.0477376 | I13: 1.21 | J13: Protection relay settings revised | K13: Pass | L13: Pass | M13: Pass | N13: Low | O13: Relay template updated
A14: ST-11 | B14: B | C14: Operating | D14: 42811 | E14: Active | F14: 0.26 | G14: 0.966 | H14: =F14*8760*G14/1000 -> 2.2001616 | I14: 1.26 | J14: Condensate corrosion risk mitigated | K14: Pass | L14: Pass | M14: Pass | N14: Medium | O14: SS316 standard
A15: ST-12 | B15: B | C15: Filtered out | D15: N/A | E15: Eliminated pre-execution | F15: 0 | G15: 0 | H15: 0 | I15: 0 | J15: Installation risk / confined space unacceptable | K15: Fail | L15: N/A | M15: N/A | N15: Closed | O15: Pre-execution elimination
A16: ST-13 | B16: B | C16: Operating | D16: 42846 | E16: Active | F16: 0.24 | G16: 0.986 | H16: =F16*8760*G16/1000 -> 2.0729664 | I16: 1.2 | J16: Grid interconnection study required | K16: Pass | L16: Pass | M16: Pass | N16: Low | O16: Grid study template
A17: ST-14 | B17: B | C17: Operating | D17: 42874 | E17: Active | F17: 0.23 | G17: 0.979 | H17: =F17*8760*G17/1000 -> 1.9724892 | I17: 1.19 | J17: Operator access training required | K17: Pass | L17: Pass | M17: Pass | N17: Low | O17: Training package
A20: Risk ID | B20: Category | C20: Risk Event | D20: Probability | E20: Impact | F20: Rating | G20: Mitigation / Control | H20: Status | J20: Attrition Metric | K20: Count | L20: Formula / Trace | M20: Status
A21: R-001 | B21: Hydraulic | C21: Duty point drift reduces PAT output | D21: Medium | E21: High | F21: High | G21: Quarterly duty point review and curve revalidation | H21: Monitored | J21: Candidates entering NPI | K21: 14 | L21: User-provided project funnel | M21: OK
A22: R-002 | B22: Mechanical | C22: Bearing vibration exceeds alarm limit | D22: Medium | E22: High | F22: High | G22: Vibration sensors, inspection and overhaul reserve | H22: Monitored | J22: Filtered before execution | K22: 2 | L22: ST-07 + ST-12 | M22: OK
A23: R-003 | B23: Electrical | C23: Relay coordination or anti-islanding failure | D23: Low | E23: High | F23: Medium | G23: Annual relay test and grid study template | H23: Controlled | J23: Installed / commissioned | K23: =K21-K22 -> 12 | L23: Candidates - filtered | M23: OK
A24: R-004 | B24: Civil | C24: No safe maintenance access | D24: Low | E24: High | F24: Medium | G24: Gate G1 envelope review; eliminated ST-07/ST-12 | H24: Closed | J24: Decommissioned after deployment | K24: 1 | L24: ST-09 | M24: Closed
A25: R-005 | B25: Controls | C25: SCADA data gaps impact revenue reporting | D25: Low | E25: Medium | F25: Low | G25: Historian tag standard and monthly data QC | H25: Controlled | J25: Operating today | K25: =COUNTIF(E4:E17,"Active") -> 11 | L25: Formula count | M25: PASS
A26: R-006 | B26: Financial | C26: CapEx exceeds $14M target | D26: Low | E26: High | F26: Medium | G26: ECN approval threshold and quarterly steering review | H26: Controlled | J26: Operating target | K26: 11 | L26: User requirement | M26: PASS
A27: R-007 | B27: Financial | C27: OPEX erodes 5-year payback | D27: Medium | E27: Medium | F27: Medium | G27: OPEX dashboard and lifecycle reserve | H27: Monitored | J27: Operating tie-out | K27: =K25-K26 -> 0 | L27: 0 = PASS | M27: PASS
A28: R-008 | B28: Operations | C28: Uptime below 96% threshold | D28: Low | E28: High | F28: Medium | G28: Monthly O&M review with escalation below threshold | H28: Controlled
A29: R-009 | B29: HSE | C29: LOTO or bypass procedure not followed | D29: Low | E29: Very High | F29: Medium | G29: HAZOP/LOTO closure and annual training | H29: Controlled
A30: R-010 | B30: Procurement | C30: PAT or generator lead time delays commissioning | D30: Medium | E30: Medium | F30: Medium | G30: Supplier quote package and long-lead tracker | H30: Closed
A31: R-011 | B31: Reliability | C31: Field attrition repeats after ST-09 failure | D31: Low | E31: High | F31: Medium | G31: Failure mode added to DVP&R and design standard | H31: Controlled
A32: R-012 | B32: Data | C32: External workbook link corrupts steering report refresh | D32: Low | E32: Medium | F32: Low | G32: Local formulas and external link break completed | H32: Closed
A33: R-013 | B33: Cyber / OT | C33: Historian access not governed | D33: Low | E33: High | F33: Medium | G33: OT access review and historian naming governance | H33: Controlled
A34: R-014 | B34: Commercial | C34: Tariff sensitivity reduces IRR below hurdle | D34: Medium | E34: High | F34: High | G34: Quarterly sensitivity review and operating cost control | H34: Monitored
A35: R-015 | B35: Environmental | C35: Flooding or drainage event damages skid | D35: Low | E35: High | F35: Medium | G35: Drain/sump mod and inspection checklist | H35: Controlled
A36: R-016 | B36: Quality | C36: As-built records not synchronized to PLM | D36: Low | E36: Medium | F36: Low | G36: Quality dossier and PLM release checklist | H36: Controlled
A41: Project Risk | C41: Related Stakeholders | E41: Date | O41: Likelihood: Chance of risk
O42: Rare: Slim possibility of happening
O43: Unlikely: Could occur but remote
O44: Possible: Might happen
O45: Likely: Expected to occur
O46: Almost Certain: Expected regularly
A47: Risk Matrix | C47: Severity
...

Sheet Cost Benefit Analysis
A1: COST-BENEFIT ANALYSIS: CAPEX, OPEX, ROI & IRR | D1: PROJECT: Multi-Site Pressure Reducing & Power Generation
A3: Input / Output | B3: Value | C3: Unit | D3: Type | E3: Source / Notes | F3: Status
A4: Target EPC CapEx | B4: 14 | C4: M$ | D4: Input | E4: User-provided target EPC CapEx | F4: OK
A5: Target Payback | B5: 5 | C5: years | D5: Input | E5: User-provided target payback | F5: OK
A6: Target IRR Low | B6: 0.1 | C6: % | D6: Input | E6: User-provided lower hurdle | F6: OK
A7: Target IRR High | B7: 0.13 | C7: % | D7: Input | E7: User-provided upper hurdle | F7: OK
A8: Pilot CapEx | B8: 0.75 | C8: M$ | D8: Input | E8: 0.25 MW pilot program | F8: OK
A9: Pilot Capacity | B9: 0.25 | C9: MW | D9: Input | E9: Pilot capacity | F9: OK
A10: Pilot Development Duration | B10: 18 | C10: months | D10: Input | E10: Development duration | F10: OK
A11: Candidate Stations | B11: 14 | C11: count | D11: Input | E11: NPI candidate funnel | F11: OK
A12: Eliminated Pre-Execution | B12: 2 | C12: count | D12: Input | E12: Site risk / space constraints | F12: OK
A13: Decommissioned Post-Install | B13: 1 | C13: count | D13: Input | E13: ST-09 field attrition | F13: OK
A14: Operating Stations | B14: =B11-B12-B13 -> 11 | C14: count | D14: Formula | E14: 14 candidates - 2 filtered - 1 decommissioned | F14: PASS
A15: Avg Capacity per Operating Station | B15: 0.25 | C15: MW | D15: Input | E15: PAT package design basis | F15: OK
A16: Operating Uptime / Availability | B16: 0.975 | C16: % | D16: Input | E16: Within 96–99% uptime KPI band | F16: OK
A17: Blended Revenue Tariff | B17: 0.175 | C17: $/kWh | D17: Input | E17: Commercial assumption; M$/GWh equivalent | F17: OK
A18: Fixed O&M | B18: 0.649 | C18: M$/yr | D18: Input | E18: Staffing, inspections, insurance, compliance | F18: OK
A19: Variable O&M Rate | B19: 0.02815 | C19: M$/GWh | D19: Input | E19: Wear parts, spares, condition monitoring | F19: OK
A21: Economic Output | B21: Value | C21: Unit | D21: Formula / Logic | E21: Target / Threshold | F21: Status
A22: Installed Operating Capacity | B22: =B14*B15 -> 2.75 | C22: MW | D22: Operating stations × 0.25 MW | E22: n/a | F22: OK
A23: Annual Net Generation | B23: =B22*8760*B16/1000 -> 23.48775 | C23: GWh/yr | D23: Capacity × hours × uptime | E23: n/a | F23: OK
A24: Gross Revenue | B24: =B23*B17 -> 4.1103562 | C24: M$/yr | D24: GWh × $/kWh | E24: n/a | F24: OK
A25: Variable O&M | B25: =B23*B19 -> 0.66118016 | C25: M$/yr | D25: GWh × variable O&M rate | E25: n/a | F25: OK
A26: Total OPEX | B26: =B18+B25 -> 1.3101802 | C26: M$/yr | D26: Fixed + variable O&M | E26: n/a | F26: OK
A27: EBITDA before Reserve | B27: =B24-B26 -> 2.8001761 | C27: M$/yr | D27: Gross revenue - total OPEX | E27: n/a | F27: OK
A28: Simple Payback | B28: =B4/B27 -> 4.9996856 | C28: years | D28: Target EPC CapEx / EBITDA | E28: ≤ 5.0 | F28: PASS
A29: Lifecycle Reserve | B29: 0.3 | C29: M$/yr | D29: Major overhaul reserve | E29: n/a | F29: OK
A30: Annual Net Operating Cash Flow | B30: =B27-B29 -> 2.5001761 | C30: M$/yr | D30: EBITDA less lifecycle reserve | E30: n/a | F30: OK
A31: Project IRR | B31: =IRR(B36:L36) -> 0.11752054 | C31: % | D31: 10-year unlevered cash flow incl. ramp/residual | E31: 10–13% | F31: PASS
A32: IRR Hurdle Check | B32: =IF(AND(B31>=B6,B31<=B7),"PASS","REVIEW") -> PASS | C32: status | D32: Within user-provided range | E32: 10–13% | F32: PASS
A33: Payback Check | B33: =IF(B28<=B5,"PASS","REVIEW") -> PASS | C33: status | D33: Simple payback vs target | E33: ≤ 5.0 years | F33: PASS
A35: Cash Flow Year | B35: 0 | C35: 1 | D35: 2 | E35: 3 | F35: 4 | G35: 5 | H35: 6 | I35: 7 | J35: 8 | K35: 9 | L35: 10
A36: Unlevered FCF M$ | B36: =-B4 -> -14 | C36: =B30*85% -> 2.1251497 | D36: =B30*95% -> 2.3751673 | E36: =B30 -> 2.5001761 | F36: =B30 -> 2.5001761 | G36: =B30 -> 2.5001761 | H36: =B30 -> 2.5001761 | I36: =B30 -> 2.5001761 | J36: =B30 -> 2.5001761 | K36: =B30 -> 2.5001761 | L36: =B30+0.5 -> 3.0001761
A39: Sensitivity | B39: Downside | C39: Base | D39: Upside | E39: Notes | F39: Status
A40: Tariff $/kWh | B40: 0.155 | C40: 0.175 | D40: 0.195 | E40: Commercial revenue sensitivity | F40: Monitor
A41: Availability | B41: 0.96 | C41: 0.975 | D41: 0.99 | E41: Uptime KPI range | F41: PASS
A42: EBITDA M$/yr | B42: =$B$22*8760*B41/1000*B40-($B$18+($B$22*8760*B41/1000)*$B$19) -> 2.2845838 | C42: =$B$22*8760*C41/1000*C40-($B$18+($B$22*8760*C41/1000)*$B$19) -> 2.8001761 | D42: =$B$22*8760*D41/1000*D40-($B$18+($B$22*8760*D41/1000)*$B$19) -> 3.3302223 | E42: Directional sensitivity | F42: OK
A43: Payback yrs | B43: =$B$4/B42 -> 6.1280307 | C43: =$B$4/C42 -> 4.9996856 | D43: =$B$4/D42 -> 4.2039235 | E43: Lower is better | F43: OK
A44: Steering cadence | B44: Monthly ops | C44: Quarterly steering | D44: Escalate below 96% uptime | E44: Governance rule | F44: Live

Sheet Dashboard
A1: EXECUTIVE DASHBOARD: Multi-Site Pressure Reducing & Power Generation PLM Portfolio
A3: KPI | B3: Value | C3: Unit | D3: Target / Band | E3: Status | F3: Interpretation | G3: KPI | H3: Value | I3: Unit | J3: Status
A4: Target EPC CapEx | B4: ='Cost Benefit Analysis'!B4 -> 14 | C4: M$ | D4: $14.0M | E4: PASS | F4: Portfolio tied to EPC target | G4: Operating stations | H4: ='Cost Benefit Analysis'!B14 -> 11 | I4: count | J4: PASS
A5: Simple Payback | B5: ='Cost Benefit Analysis'!B28 -> 4.9996856 | C5: years | D5: ≤5.0 | E5: PASS | F5: Meets user hurdle before financing | G5: Project IRR | H5: ='Cost Benefit Analysis'!B31 -> 0.11752054 | I5: % | J5: PASS
A6: Annual Generation | B6: ='Cost Benefit Analysis'!B23 -> 23.48775 | C6: GWh/yr | D6: n/a | E6: OK | F6: 11 active stations at 97.5% availability | G6: Uptime KPI | H6: ='Cost Benefit Analysis'!B16 -> 0.975 | I6: % | J6: PASS
A7: Gross Revenue | B7: ='Cost Benefit Analysis'!B24 -> 4.1103562 | C7: M$/yr | D7: n/a | E7: OK | F7: Tariff-linked energy recovery revenue | G7: OPEX | H7: ='Cost Benefit Analysis'!B26 -> 1.3101802 | I7: M$/yr | J7: OK
A8: Candidate Stations | B8: 14 | C8: count | D8: 14 | E8: OK | F8: NPI funnel entry count | G8: Filtered | H8: 2 | I8: count | J8: OK
A9: Installed / Commissioned | B9: 12 | C9: count | D9: 12 | E9: OK | F9: One installed station decommissioned | G9: Decommissioned | H9: 1 | I9: count | J9: Closed
A10: Steering Cadence | B10: Monthly / Quarterly | C10: cadence | D10: Ops / Steering | E10: Live | F10: Monthly KPI review; quarterly steering | G10: Link Prompt | H10: Removed / local formulas | I10: status | J10: PASS
A13: Lifecycle Stage | B13: Gate | C13: Start | D13: Finish / Release | E13: Status | F13: Main Evidence | H13: Attrition Funnel | I13: Stations | J13: Notes
A14: Project Proposal | B14: G0 | C14: 2012-01 | D14: 2012-03 | E14: Complete | F14: PLM baseline + business case | H14: Candidate stations | I14: 14 | J14: NPI entry
A15: Pre-Execution Feasibility | B15: G1 | C15: 2012-04 | D15: 2012-12 | E15: Complete | F15: 14 candidates screened; 2 removed | H15: Pre-execution eliminated | I15: 2 | J15: ST-07/ST-12
A16: Design | B16: G2 | C16: 2013-01 | D16: 2014-10 | E16: Complete | F16: EBOM/MBOM, HAZOP, grid study | H16: Installed / commissioned | I16: 12 | J16: After feasibility
A17: Validation & Testing | B17: G3 | C17: 2014-11 | D17: 2015-09 | E17: Complete | F17: Pilot, FAT/SAT, DVP&R | H17: Post-install decommissioned | I17: 1 | J17: ST-09
A18: Commissioning | B18: G4 | C18: 2015-10 | D18: 2016-07 | E18: Complete | F18: Wet commissioning + grid sync | H18: Operating today | I18: 11 | J18: Active assets
A19: O&M | B19: G5 | C19: 2017-01 | D19: Present | E19: Live | F19: 11 operating stations; KPI governance
A20: Field Feedback | B20: G5-FB | C20: 2019-03 | D20: Closed | E20: Closed | F20: ST-09 failure data fed back to PLM
A23: Management Takeaway | B23: Detail | C23: Owner | D23: Cadence | E23: Escalation Trigger | F23: Status | G23: Evidence Sheet | H23: Cell / Range | I23: Next Action | J23: Due
A24: Economic case meets hurdle | B24: Payback near 5 years and IRR in 10–13% band | C24: Finance | D24: Quarterly | E24: IRR <10% or payback >5.0 | F24: PASS | G24: Cost Benefit Analysis | H24: A21:F36 | I24: Maintain OPEX and uptime discipline | J24: 2026-Q3
A25: Technical envelope stable | B25: 11 operating stations have accepted release evidence | C25: Systems Eng. | D25: Monthly | E25: Any uptime <96% | F25: PASS | G25: Validation & Release Management | H25: A12:J26 | I25: Continue vibration trend review | J25: Monthly
A26: Attrition captured correctly | B26: 14 candidates, 2 pre-execution filters, 1 decommissioned, 11 active | C26: PMO | D26: Quarterly | E26: Uncontrolled field attrition | F26: PASS | G26: Risk Management | H26: A3:O17 | I26: Keep ST-09 lessons linked | J26: Closed
A27: Change governance improved | B27: ECNs tie engineering changes to technical and financial disposition | C27: PLM Admin | D27: Monthly | E27: Critical ECN without approval | F27: PASS | G27: Change Management (ECN) | H27: A3:Q18 | I27: Audit ECN approvals | J27: 2026-Q3
A28: External links resolved | B28: Workbook uses local formulas and link prompt status is tracked | C28: PLM Admin | D28: At release | E28: Open update-link prompt | F28: PASS | G28: Dashboard | H28: A4:J10 | I28: Verify on next open | J28: Next open
A29: Operational cadence live | B29: Monthly KPI review plus quarterly steering escalation path | C29: Operations | D29: Monthly / Quarterly | E29: Uptime <96%, cost breach | F29: LIVE | G29: Executive Report | H29: A1:H36 | I29: Use refreshed steering pack | J29: 2026-Q3
A30: PLM data model consistent | B30: Document, BOM, Change, ECN, Validation, Risk and CBA objects aligned | C30: PLM Admin | D30: Quarterly | E30: Broken traceability | F30: PASS | G30: Documents Management | H30: A5:H24 | I30: Refresh Teamcenter export | J30: 2026-Q3
A33: Dashboard Data
A35: MONTHLY PERFORMANCE DATA
A36: Month | B36: Revenue | C36: COGS | D36: Gross Profit | E36: Expenses | F36: Net Profit | G36: Revenue Target | H36: Customers | I36: Avg Order Value
A37: Jan | B37: 285000 | C37: 119700 | D37: =B37-C37 -> 165300 | E37: 95000 | F37: =D37-E37 -> 70300 | G37: 300000 | H37: 142 | I37: =B37/H37 -> 2007.0423
A38: Feb | B38: 310000 | C38: 127100 | D38: =B38-C38 -> 182900 | E38: 98000 | F38: =D38-E38 -> 84900 | G38: 320000 | H38: 155 | I38: =B38/H38 -> 2000
A39: Mar | B39: 340000 | C39: 136000 | D39: =B39-C39 -> 204000 | E39: 102000 | F39: =D39-E39 -> 102000 | G39: 340000 | H39: 170 | I39: =B39/H39 -> 2000
A40: Apr | B40: 325000 | C40: 136500 | D40: =B40-C40 -> 188500 | E40: 100000 | F40: =D40-E40 -> 88500 | G40: 360000 | H40: 163 | I40: =B40/H40 -> 1993.865
A41: May | B41: 365000 | C41: 146000 | D41: =B41-C41 -> 219000 | E41: 105000 | F41: =D41-E41 -> 114000 | G41: 380000 | H41: 182 | I41: =B41/H41 -> 2005.4945
A42: Jun | B42: 390000 | C42: 152100 | D42: =B42-C42 -> 237900 | E42: 108000 | F42: =D42-E42 -> 129900 | G42: 400000 | H42: 195 | I42: =B42/H42 -> 2000
A43: Jul | B43: 375000 | C43: 153750 | D43: =B43-C43 -> 221250 | E43: 106000 | F43: =D43-E43 -> 115250 | G43: 400000 | H43: 188 | I43: =B43/H43 -> 1994.6809
A44: Aug | B44: 410000 | C44: 159900 | D44: =B44-C44 -> 250100 | E44: 112000 | F44: =D44-E44 -> 138100 | G44: 420000 | H44: 205 | I44: =B44/H44 -> 2000
A45: Sep | B45: 425000 | C45: 161500 | D45: =B45-C45 -> 263500 | E45: 115000 | F45: =D45-E45 -> 148500 | G45: 440000 | H45: 213 | I45: =B45/H45 -> 1995.3052
A46: Oct | B46: 450000 | C46: 171000 | D46: =B46-C46 -> 279000 | E46: 118000 | F46: =D46-E46 -> 161000 | G46: 460000 | H46: 225 | I46: =B46/H46 -> 2000
A47: Nov | B47: 470000 | C47: 173900 | D47: =B47-C47 -> 296100 | E47: 120000 | F47: =D47-E47 -> 176100 | G47: 480000 | H47: 235 | I47: =B47/H47 -> 2000
A48: Dec | B48: 520000 | C48: 187200 | D48: =B48-C48 -> 332800 | E48: 125000 | F48: =D48-E48 -> 207800 | G48: 500000 | H48: 260 | I48: =B48/H48 -> 2000
...

Sheet Executive Report
A1: EXECUTIVE REPORT — Full Lifecycle Delivery for Multi-Site Pressure Reducing & Power Generation
A3: Section | B3: Finding / Report Detail | C3: Technical Evidence | D3: Financial Evidence | E3: Operational Evidence | F3: Governance / Escalation | G3: Owner | H3: Status
A4: Executive summary | B4: Portfolio rebuilt as PLM program covering design, validation, commissioning and O&M | C4: Controlled documents, EBOM/MBOM and ECN board rebuilt | D4: Target EPC CapEx $14.0M, payback 5 years, IRR 10–13% | E4: 11 stations operating under KPI review | F4: Monthly ops; quarterly steering | G4: PMO | H4: PASS
A5: Lifecycle ownership | B5: Delivery model is explicitly Project Proposal → Design → Validation & Testing → Commissioning → O&M | C5: Stage-gate sheet maps G0 through G5-FB | D5: Economics tied to gates | E5: O&M release includes uptime controls | F5: Assigned gate owners | G5: PLM Manager | H5: PASS
A6: NPI attrition | B6: 14 candidate stations, 2 filtered before execution, 1 decommissioned after installation, 11 active | C6: Risk sheet lists all 14 stations | D6: Avoided CapEx from removed sites; ST-09 learning captured | E6: Operating count formula-checks to 11 | F6: Reliability board escalation | G6: PMO | H6: PASS
A7: Pre-execution filtering | B7: ST-07 and ST-12 eliminated for site installation risk and physical space constraints | C7: Gate G1 civil envelope checks failed | D7: No stranded execution CapEx | E7: Risks closed before construction | F7: Steering approval | G7: Civil Lead | H7: Closed
A8: Post-install field attrition | B8: ST-09 decommissioned after bearing/vibration failures and failure data fed back to DVP&R | C8: Failure mode linked to validation and risk register | D8: OPEX drag reduced | E8: Reliability monitoring upgraded | F8: Reliability Board | G8: Reliability | H8: Closed
A9: Technical architecture | B9: Station package includes PAT/turbine, generator, bypass valves, stainless pipe spools, MCC/protection, SCADA/historian and instrumentation | C9: BOM includes controlled items and revisions | D9: Reference station MBOM cost summarized | E9: SCADA supports KPI reporting | F9: ECN approvals | G9: Systems Eng. | H9: Released
A10: Pilot program | B10: Pilot captured as $0.75M CapEx, 0.25 MW and 18-month development duration | C10: Pilot closeout and test evidence included | D10: Pilot informs EPC target case | E10: Pilot lessons transferred to design freeze | F10: G3 validation closeout | G10: PMO | H10: Released
A11: Portfolio capacity | B11: 11 operating stations × 0.25 MW average capacity = 2.75 MW operating capacity | C11: Risk station table formulas calculate energy | D11: Generation from capacity × uptime | E11: Uptime aligns to 96–99% KPI | F11: Monthly review | G11: Operations | H11: PASS
A12: Energy and revenue | B12: Annual generation and revenue are calculated from capacity, uptime and $0.175/kWh tariff | C12: CBA bridge transparent | D12: Gross revenue feeds payback and IRR | E12: Revenue metric tied to dashboard | F12: Quarterly finance refresh | G12: Finance | H12: PASS
A13: OPEX model | B13: OPEX includes fixed inspection/compliance plus variable wear/spares and lifecycle reserve | C13: O&M spare kit and reserve in BOM/CBA | D13: OPEX sensitivity visible | E13: Monthly OPEX review controls payback | F13: Steering escalation | G13: O&M / Finance | H13: PASS
A14: Economic hurdle | B14: Target EPC CapEx $14M, payback ≤5 years and IRR 10–13% are embedded as checks | C14: CBA shows formulas and hurdle checks | D14: Payback/IRR surfaced on dashboard | E14: Operating KPIs support durability | F14: Quarterly steering | G14: Finance | H14: PASS
... A32: Final QA | B32: No formula errors or visible external workbook formula links found after local formula rebuild; verify startup prompt on next open. | C32: Workbook search/verification follows | D32: CBA and dashboard tie-outs included | E32: Formula checks are visible | F32: Release checklist | G32: PLM Admin | H32: PASS
